Workbook

Sheet Summary
A1: Milano Transit Live — progress by phase
A2: Counts come from the Roadmap sheet.
A4: Phase | B4: Done | C4: In progress | D4: Next | E4: Planned | F4: Later | G4: Waiting on Giovanni | H4: Total | I4: % done
A5: 0 Foundation | B5: =COUNTIFS(Roadmap!$B$5:$B$300,$A5,Roadmap!$E$5:$E$300,"Done") -> 20 | C5: =COUNTIFS(Roadmap!$B$5:$B$300,$A5,Roadmap!$E$5:$E$300,"In progress") -> 0 | D5: =COUNTIFS(Roadmap!$B$5:$B$300,$A5,Roadmap!$E$5:$E$300,"Next") -> 0 | E5: =COUNTIFS(Roadmap!$B$5:$B$300,$A5,Roadmap!$E$5:$E$300,"Planned") -> 0 | F5: =COUNTIFS(Roadmap!$B$5:$B$300,$A5,Roadmap!$E$5:$E$300,"Later") -> 0 | G5: =COUNTIFS(Roadmap!$B$5:$B$300,$A5,Roadmap!$E$5:$E$300,"Waiting on Giovanni") -> 2 | H5: =COUNTIF(Roadmap!$B$5:$B$300,$A5) -> 22 | I5: =IF(H5=0,0,B5/H5) -> 0.90909091
A6: 1 M3 playable | B6: =COUNTIFS(Roadmap!$B$5:$B$300,$A6,Roadmap!$E$5:$E$300,"Done") -> 4 | C6: =COUNTIFS(Roadmap!$B$5:$B$300,$A6,Roadmap!$E$5:$E$300,"In progress") -> 0 | D6: =COUNTIFS(Roadmap!$B$5:$B$300,$A6,Roadmap!$E$5:$E$300,"Next") -> 4 | E6: =COUNTIFS(Roadmap!$B$5:$B$300,$A6,Roadmap!$E$5:$E$300,"Planned") -> 10 | F6: =COUNTIFS(Roadmap!$B$5:$B$300,$A6,Roadmap!$E$5:$E$300,"Later") -> 0 | G6: =COUNTIFS(Roadmap!$B$5:$B$300,$A6,Roadmap!$E$5:$E$300,"Waiting on Giovanni") -> 1 | H6: =COUNTIF(Roadmap!$B$5:$B$300,$A6) -> 19 | I6: =IF(H6=0,0,B6/H6) -> 0.21052632
A7: 2 Calendar | B7: =COUNTIFS(Roadmap!$B$5:$B$300,$A7,Roadmap!$E$5:$E$300,"Done") -> 0 | C7: =COUNTIFS(Roadmap!$B$5:$B$300,$A7,Roadmap!$E$5:$E$300,"In progress") -> 0 | D7: =COUNTIFS(Roadmap!$B$5:$B$300,$A7,Roadmap!$E$5:$E$300,"Next") -> 0 | E7: =COUNTIFS(Roadmap!$B$5:$B$300,$A7,Roadmap!$E$5:$E$300,"Planned") -> 2 | F7: =COUNTIFS(Roadmap!$B$5:$B$300,$A7,Roadmap!$E$5:$E$300,"Later") -> 0 | G7: =COUNTIFS(Roadmap!$B$5:$B$300,$A7,Roadmap!$E$5:$E$300,"Waiting on Giovanni") -> 0 | H7: =COUNTIF(Roadmap!$B$5:$B$300,$A7) -> 2 | I7: =IF(H7=0,0,B7/H7) -> 0
A8: 3 Analysis mode | B8: =COUNTIFS(Roadmap!$B$5:$B$300,$A8,Roadmap!$E$5:$E$300,"Done") -> 0 | C8: =COUNTIFS(Roadmap!$B$5:$B$300,$A8,Roadmap!$E$5:$E$300,"In progress") -> 0 | D8: =COUNTIFS(Roadmap!$B$5:$B$300,$A8,Roadmap!$E$5:$E$300,"Next") -> 0 | E8: =COUNTIFS(Roadmap!$B$5:$B$300,$A8,Roadmap!$E$5:$E$300,"Planned") -> 3 | F8: =COUNTIFS(Roadmap!$B$5:$B$300,$A8,Roadmap!$E$5:$E$300,"Later") -> 0 | G8: =COUNTIFS(Roadmap!$B$5:$B$300,$A8,Roadmap!$E$5:$E$300,"Waiting on Giovanni") -> 0 | H8: =COUNTIF(Roadmap!$B$5:$B$300,$A8) -> 3 | I8: =IF(H8=0,0,B8/H8) -> 0
A9: 4 Metro in depth | B9: =COUNTIFS(Roadmap!$B$5:$B$300,$A9,Roadmap!$E$5:$E$300,"Done") -> 0 | C9: =COUNTIFS(Roadmap!$B$5:$B$300,$A9,Roadmap!$E$5:$E$300,"In progress") -> 0 | D9: =COUNTIFS(Roadmap!$B$5:$B$300,$A9,Roadmap!$E$5:$E$300,"Next") -> 0 | E9: =COUNTIFS(Roadmap!$B$5:$B$300,$A9,Roadmap!$E$5:$E$300,"Planned") -> 0 | F9: =COUNTIFS(Roadmap!$B$5:$B$300,$A9,Roadmap!$E$5:$E$300,"Later") -> 3 | G9: =COUNTIFS(Roadmap!$B$5:$B$300,$A9,Roadmap!$E$5:$E$300,"Waiting on Giovanni") -> 1 | H9: =COUNTIF(Roadmap!$B$5:$B$300,$A9) -> 4 | I9: =IF(H9=0,0,B9/H9) -> 0
A10: 5 Buses | B10: =COUNTIFS(Roadmap!$B$5:$B$300,$A10,Roadmap!$E$5:$E$300,"Done") -> 0 | C10: =COUNTIFS(Roadmap!$B$5:$B$300,$A10,Roadmap!$E$5:$E$300,"In progress") -> 0 | D10: =COUNTIFS(Roadmap!$B$5:$B$300,$A10,Roadmap!$E$5:$E$300,"Next") -> 0 | E10: =COUNTIFS(Roadmap!$B$5:$B$300,$A10,Roadmap!$E$5:$E$300,"Planned") -> 0 | F10: =COUNTIFS(Roadmap!$B$5:$B$300,$A10,Roadmap!$E$5:$E$300,"Later") -> 2 | G10: =COUNTIFS(Roadmap!$B$5:$B$300,$A10,Roadmap!$E$5:$E$300,"Waiting on Giovanni") -> 0 | H10: =COUNTIF(Roadmap!$B$5:$B$300,$A10) -> 2 | I10: =IF(H10=0,0,B10/H10) -> 0
A11: 6 Driver rules | B11: =COUNTIFS(Roadmap!$B$5:$B$300,$A11,Roadmap!$E$5:$E$300,"Done") -> 0 | C11: =COUNTIFS(Roadmap!$B$5:$B$300,$A11,Roadmap!$E$5:$E$300,"In progress") -> 0 | D11: =COUNTIFS(Roadmap!$B$5:$B$300,$A11,Roadmap!$E$5:$E$300,"Next") -> 0 | E11: =COUNTIFS(Roadmap!$B$5:$B$300,$A11,Roadmap!$E$5:$E$300,"Planned") -> 0 | F11: =COUNTIFS(Roadmap!$B$5:$B$300,$A11,Roadmap!$E$5:$E$300,"Later") -> 1 | G11: =COUNTIFS(Roadmap!$B$5:$B$300,$A11,Roadmap!$E$5:$E$300,"Waiting on Giovanni") -> 0 | H11: =COUNTIF(Roadmap!$B$5:$B$300,$A11) -> 1 | I11: =IF(H11=0,0,B11/H11) -> 0
A12: 7 Trams | B12: =COUNTIFS(Roadmap!$B$5:$B$300,$A12,Roadmap!$E$5:$E$300,"Done") -> 0 | C12: =COUNTIFS(Roadmap!$B$5:$B$300,$A12,Roadmap!$E$5:$E$300,"In progress") -> 0 | D12: =COUNTIFS(Roadmap!$B$5:$B$300,$A12,Roadmap!$E$5:$E$300,"Next") -> 0 | E12: =COUNTIFS(Roadmap!$B$5:$B$300,$A12,Roadmap!$E$5:$E$300,"Planned") -> 0 | F12: =COUNTIFS(Roadmap!$B$5:$B$300,$A12,Roadmap!$E$5:$E$300,"Later") -> 1 | G12: =COUNTIFS(Roadmap!$B$5:$B$300,$A12,Roadmap!$E$5:$E$300,"Waiting on Giovanni") -> 0 | H12: =COUNTIF(Roadmap!$B$5:$B$300,$A12) -> 1 | I12: =IF(H12=0,0,B12/H12) -> 0
A13: Licenses & hosting | B13: =COUNTIFS(Roadmap!$B$5:$B$300,$A13,Roadmap!$E$5:$E$300,"Done") -> 0 | C13: =COUNTIFS(Roadmap!$B$5:$B$300,$A13,Roadmap!$E$5:$E$300,"In progress") -> 0 | D13: =COUNTIFS(Roadmap!$B$5:$B$300,$A13,Roadmap!$E$5:$E$300,"Next") -> 6 | E13: =COUNTIFS(Roadmap!$B$5:$B$300,$A13,Roadmap!$E$5:$E$300,"Planned") -> 1 | F13: =COUNTIFS(Roadmap!$B$5:$B$300,$A13,Roadmap!$E$5:$E$300,"Later") -> 0 | G13: =COUNTIFS(Roadmap!$B$5:$B$300,$A13,Roadmap!$E$5:$E$300,"Waiting on Giovanni") -> 0 | H13: =COUNTIF(Roadmap!$B$5:$B$300,$A13) -> 7 | I13: =IF(H13=0,0,B13/H13) -> 0
A14: All phases | B14: =SUM(B5:B13) -> 24 | C14: =SUM(C5:C13) -> 0 | D14: =SUM(D5:D13) -> 10 | E14: =SUM(E5:E13) -> 16 | F14: =SUM(F5:F13) -> 7 | G14: =SUM(G5:G13) -> 4 | H14: =SUM(H5:H13) -> 61 | I14: =IF(H14=0,0,B14/H14) -> 0.39344262

Sheet Roadmap
A1: Milano Transit Live — roadmap
A2: Edit Status and Who with the dropdowns. Add new rows at the bottom; the Summary updates by itself.
A4: # | B4: Phase | C4: Area | D4: Item | E4: Status | F4: Who | G4: Notes
A5: 1 | B5: 0 Foundation | C5: Data | D5: ATM timetable (GTFS) loaded, service day 03:00–02:59 | E5: Done | F5: Claude | G5: One weekday timetable used for Mon–Fri
A6: 2 | B6: 0 Foundation | C6: Map | D6: Satellite, Hybrid and OSM maps + rail tracks overlay | E6: Done | F6: Claude
A7: 3 | B7: 0 Foundation | C7: Network | D7: Every metro, tram and bus vehicle moving as a dot from the timetable | E7: Done | F7: Claude | G7: Trams and most buses only at timetable level
A8: 4 | B8: 0 Foundation | C8: Network | D8: 30 s stop at every metro station, 15 s at bus stops | E8: Done | F8: Both
A9: 5 | B9: 0 Foundation | C9: M3 | D9: All M3 tracks and junctions drawn from OpenStreetMap, right-hand running | E9: Done | F9: Both | G9: Porta Romana–Repubblica stacked tracks allowed to overlap
A10: 6 | B10: 0 Foundation | C10: M3 | D10: San Donato rules: arrivals on platform 3, one train per tail, cab change, departures from 1/2 with 30 s–2 min wait | E10: Done | F10: Both | G10: 0 tail clashes, 0 late departures
A11: 7 | B11: 0 Foundation | C11: M3 | D11: Comasina terminal and 2 trains overnight in the tails of both termini | E11: Done | F11: Both | G11: One evening train waits 7 min on the arrival platform (no other place)
A12: 8 | B12: 0 Foundation | C12: M3 | D12: Depot: through tracks, parking only on tracks ≥ 115 m, 15 km/h, one train per track | E12: Done | F12: Both | G12: 20 parking places
A13: 9 | B13: 0 Foundation | C13: M3 | D13: Test loop (anello di prova) on demand from every depot place | E13: Done | F13: Both | G13: 20 of 20 places
A14: 10 | B14: 0 Foundation | C14: M3 | D14: Real fleet: 24 trains with units, type and year | E14: Done | F14: Both | G14: Peak 23 trains at 07:32
A15: 11 | B15: 0 Foundation | C15: M3 | D15: Platform labels 1–2–3, platform diagram, departure platform picker | E15: Done | F15: Claude
A16: 12 | B16: 0 Foundation | C16: M3 | D16: Player order: train from Rogoredo arrives on platform 2 and reverses there | E16: Done | F16: Claude | G16: Only if platform 2 is free when ordered
A17: 13 | B17: 0 Foundation | C17: M4 | D17: M4 tracks, San Cristoforo depot, real fleet 4401–4447 | E17: Done | F17: Both
A18: 14 | B18: 0 Foundation | C18: M1 | D18: M1 trains on real tracks (10 stop patterns), platforms | E18: Done | F18: Claude | G18: Depot movements later
A19: 15 | B19: 0 Foundation | C19: Stations | D19: Station boards in Italian, "in arrivo", red "Servizio terminato" | E19: Done | F19: Both | G19: M3 in arrivo < 1:30, M4 < 30 s
A20: 16 | B20: 0 Foundation | C20: Buses | D20: Line 130: 7 buses, 18 m articulated, H stops | E20: Done | F20: Claude
A21: 17 | B21: 0 Foundation | C21: Buses | D21: Line 64: 11 buses, 12 m, ATM-style stop display + stop timetable | E21: Done | F21: Claude
A22: 18 | B22: 0 Foundation | C22: Editor | D22: Track editor: track use, 5 signal types, draw missing tracks, export | E22: Done | F22: Claude
A23: 19 | B23: 0 Foundation | C23: Editor | D23: Your 7 M3 signals saved into the build | E23: Done | F23: Giovanni
A24: 20 | B24: 0 Foundation | C24: Game | D24: Admin / Player modes, M3 control panel with delay colours | E24: Done | F24: Claude
A25: 21 | B25: 0 Foundation | C25: Editor | D25: Mark the depot X tracks as "movements only, no parking" | E25: Waiting on Giovanni | F25: Giovanni | G25: Send the export, Claude rebuilds
A26: 22 | B26: 0 Foundation | C26: Editor | D26: Place the 2 stops on the anello di prova | E26: Waiting on Giovanni | F26: Giovanni | G26: Signal type "stop"
A27: 23 | B27: 1 M3 playable | C27: Project | D27: Public GitHub repo, project split into files | E27: Next | F27: Claude | G27: Open from day one
A28: 24 | B28: 1 M3 playable | C28: Project | D28: Automatic tests (tails, depot, late departures) run on every change | E28: Next | F28: Claude
A29: 25 | B29: 1 M3 playable | C29: Engine | D29: Live simulation engine in the browser (JavaScript, background worker) | E29: Planned | F29: Claude | G29: Replaces the precomputed day
A30: 26 | B30: 1 M3 playable | C30: Signals | D30: Block sections built from your signals | E30: Planned | F30: Both
A31: 27 | B31: 1 M3 playable | C31: Signals | D31: Junctions locked for a route before a train passes | E31: Planned | F31: Claude
A32: 28 | B32: 1 M3 playable | C32: Signals | D32: Player sees block signals and all signals | E32: Planned | F32: Claude
A33: 29 | B33: 1 M3 playable | C33: Engine | D33: Every delay records its cause (what should happen / what happened / why) | E33: Planned | F33: Claude
A34: 30 | B34: 1 M3 playable | C34: Game | D34: First scenario: fault San Donato–Rogoredo | E34: Planned | F34: Both
A35: 31 | B35: 1 M3 playable | C35: Game | D35: Player controls: hold a train, turn back at Rogoredo, close a section, replacement bus | E35: Planned | F35: Both | G35: Chiusura tratte
A36: 32 | B36: 1 M3 playable | C36: Game | D36: Score: minutes of delay + runs cancelled | E36: Planned | F36: Claude | G36: No passenger model
A37: 33 | B37: 2 Calendar | C37: Data | D37: Real dates: Saturday, Sunday, holidays from the timetable feed | E37: Planned | F37: Claude | G37: Date picker replaces Lun–Ven
A38: 34 | B38: 2 Calendar | C38: Data | D38: Christmas, New Year's Eve and reduced-service days | E38: Planned | F38: Both | G38: From your PDFs if the feed does not cover them
A39: 35 | B39: 3 Analysis mode | C39: Analysis | D39: Plan vs what happened, with the cause of every delay | E39: Planned | F39: Claude
A40: 36 | B40: 3 Analysis mode | C40: Analysis | D40: Indicators: gaps between trains, lateness, runs lost | E40: Planned | F40: Claude
A41: 37 | B41: 3 Analysis mode | C41: Analysis | D41: Compare two what-if runs and export a report | E41: Planned | F41: Claude
...

Sheet Lists
A1: 0 Foundation
A2: 1 M3 playable
A3: 2 Calendar
A4: 3 Analysis mode
A5: 4 Metro in depth
A6: 5 Buses
A7: 6 Driver rules
A8: 7 Trams
A9: Licenses & hosting
